Workbook

Sheet Customers
A1: customer_id | B1: customer_name | C1: email | D1: city | E1: state | F1: segment | G1: signup_date
A2: 1 | B2: Linda Smith | C2: linda.smith1@example.com | D2: Dallas | E2: TX | F2: Consumer | G2: 2023-09-08
A3: 2 | B3: Robert Smith | C3: robert.smith2@example.com | D3: Chicago | E3: IL | F3: Small Business | G3: 2023-08-12
A4: 3 | B4: Joseph Anderson | C4: joseph.anderson3@example.com | D4: Mexico City | E4: CDMX | F4: Corporate | G4: 2023-10-12
A5: 4 | B5: Susan Harris | C5: susan.harris4@example.com | D5: Miami | E5: FL | F5: Consumer | G5: 2023-04-15
A6: 5 | B6: Luis Brown | C6: luis.brown5@example.com | D6: Boston | E6: MA | F6: Small Business | G6: 2023-03-22
A7: 6 | B7: John Johnson | C7: john.johnson6@example.com | D7: San Diego | E7: CA | F7: Corporate | G7: 2023-10-24
A8: 7 | B8: Lisa Garcia | C8: lisa.garcia7@example.com | D8: Atlanta | E8: GA | F8: Small Business | G8: 2023-12-30
A9: 8 | B9: Luis White | C9: luis.white8@example.com | D9: San Diego | E9: CA | F9: Consumer | G9: 2023-06-17
A10: 9 | B10: Patricia Davis | C10: patricia.davis9@example.com | D10: Los Angeles | E10: CA | F10: Small Business | G10: 2023-11-20
A11: 10 | B11: Valentina Gonzalez | C11: valentina.gonzalez10@example.com | D11: Denver | E11: CO | F11: Small Business | G11: 2023-05-27
A12: 11 | B12: Mariana Gonzalez | C12: mariana.gonzalez11@example.com | D12: Atlanta | E12: GA | F12: Consumer | G12: 2023-08-13
A13: 12 | B13: David Sanchez | C13: david.sanchez12@example.com | D13: Seattle | E13: WA | F13: Small Business | G13: 2024-09-02
... A15: 14 | B15: Camila Smith | C15: camila.smith14@example.com | D15: Dallas | E15: TX | F15: Small Business | G15: 2024-05-27
A16: 15 | B16: Richard Jones | D16: Atlanta | E16: GA | F16: Corporate | G16: 2023-06-15
A17: 16 | B17: Linda Robinson | C17: linda.robinson16@example.com | D17: Atlanta | E17: GA | F17: Small Business | G17: 2023-11-11
A18: 17 | B18: John Harris | C18: john.harris17@example.com | D18: Toronto | E18: ON | F18: Small Business | G18: 2023-05-09
A19: 18 | B19: Susan Robinson | C19: susan.robinson18@example.com | D19: Toronto | E19: ON | F19: Corporate | G19: 2024-12-07
A20: 19 | B20: Juan Brown | C20: juan.brown19@example.com | D20: San Diego | E20: CA | F20: Consumer | G20: 2023-08-19
A21: 20 | B21: Patricia Davis | C21: patricia.davis20@example.com | D21: Chicago | E21: IL | F21: Consumer | G21: 2023-02-02
A22: 21 | B22: Diego Jackson | C22: diego.jackson21@example.com | D22: Bogota | E22: DC | F22: Corporate | G22: 2023-09-06
A23: 22 | B23: Mark Anderson | C23: mark.anderson22@example.com | D23: Los Angeles | E23: CA | F23: Consumer | G23: 2024-11-20
A24: 23 | B24: Richard Moore | C24: richard.moore23@example.com | D24: Denver | E24: CO | F24: Corporate | G24: 2023-05-24
A25: 24 | B25: Isabella Brown | C25: isabella.brown24@example.com | D25: Los Angeles | E25: CA | F25: Consumer | G25: 2024-10-29
A26: 25 | B26: Valentina Thomas | D26: San Antonio | E26: TX | F26: Corporate | G26: 2024-02-15
A27: 26 | B27: Camila Martinez | C27: camila.martinez26@example.com | D27: Seattle | E27: WA | F27: Consumer | G27: 2024-12-14
A28: 27 | B28: Susan Johnson | C28: susan.johnson27@example.com | D28: Mexico City | E28: CDMX | F28: Small Business | G28: 2024-07-09
A29: 28 | B29: Carlos Williams | C29: carlos.williams28@example.com | D29: Philadelphia | E29: PA | F29: Small Business | G29: 2023-03-12
A30: 29 | B30: Miguel Johnson | C30: miguel.johnson29@example.com | D30: Chicago | E30: IL | F30: Small Business | G30: 2024-03-05
A31: 30 | B31: Jessica Rodriguez | C31: jessica.rodriguez30@example.com | D31: Boston | E31: MA | F31: Unknown | G31: 2023-05-15
A32: 31 | B32: Laura Jackson | C32: laura.jackson31@example.com | D32: Houston | E32: TX | F32: Consumer | G32: 2023-03-17
A33: 32 | B33: Lisa Martinez | C33: lisa.martinez32@example.com | D33: Philadelphia | E33: PA | F33: Small Business | G33: 2024-03-24
A34: 33 | B34: Isabella Martinez | C34: isabella.martinez33@example.com | D34: Houston | E34: TX | F34: Corporate | G34: 2023-05-18
A35: 34 | B35: Nancy Miller | C35: nancy.miller34@example.com | D35: Dallas | E35: TX | F35: Corporate | G35: 2024-06-01
A36: 35 | B36: Robert Smith | C36: robert.smith35@example.com | D36: Miami | E36: FL | F36: Corporate | G36: 2023-05-14
A37: 36 | B37: Linda Williams | C37: linda.williams36@example.com | D37: Phoenix | E37: AZ | F37: Consumer | G37: 2024-07-12
A38: 37 | B38: Robert Lewis | C38: robert.lewis37@example.com | D38: Atlanta | E38: GA | F38: Corporate | G38: 2023-08-04
A39: 38 | B39: Elizabeth Robinson | D39: San Diego | E39: CA | F39: Small Business | G39: 2023-06-16
A40: 39 | B40: Mark Sanchez | C40: mark.sanchez39@example.com | D40: San Diego | E40: CA | F40: Corporate | G40: 2023-10-01
A41: 40 | B41: Camila Lopez | C41: camila.lopez40@example.com | D41: Austin | E41: TX | F41: Consumer | G41: 2023-08-22
...

Sheet Products
A1: product_id | B1: product_name | C1: category | D1: unit_cost | E1: unit_price
A2: 1 | B2: Wireless Mouse | C2: Electronics | D2: 152.94 | E2: 327.32
A3: 2 | B3: Mechanical Keyboard | C3: Electronics | D3: 294.14 | E3: 498.15
A4: 3 | B4: USB-C Hub | C4: Electronics | D4: 66.63 | E4: 89.39
A5: 4 | B5: 27in Monitor | C5: Electronics | D5: 27.94 | E5: 56.24
A6: 5 | B6: Webcam HD | C6: Electronics | D6: 242.44 | E6: 439.06
A7: 6 | B7: Noise Cancelling Headset | C7: Electronics | D7: 13.13 | E7: 28.51
A8: 7 | B8: Portable SSD 1TB | C8: Electronics | D8: 333.81 | E8: 460
A9: 8 | B9: Laptop Stand | C9: Electronics | D9: 76.82 | E9: 104.4
A10: 9 | B10: Bluetooth Speaker | C10: Electronics | D10: 125.18 | E10: 203.1
A11: 10 | B11: Wireless Mouse | C11: Electronics | D11: 175.62 | E11: 251.58
A12: 11 | B12: Mechanical Keyboard | C12: Electronics | D12: 246.68 | E12: 328.39
A13: 12 | B13: USB-C Hub | C13: Electronics | D13: 120.4 | E13: 179.23
... A61: 60 | B61: Conference Table | C61: Furniture | D61: 357.56 | E61: 584.98

Sheet Orders
A1: order_id | B1: customer_id | C1: product_id | D1: order_date | E1: quantity | F1: unit_price | G1: discount | H1: order_status | I1: net_revenue | J1: customer_segment | K1: product_category | L1: order_month
A2: 1 | B2: 324 | C2: 10 | D2: 2023-06-21 | E2: 7 | F2: 251.58 | G2: 0.15 | H2: Completed | I2: 1496.9 | J2: =VLOOKUP(B2,Customers!$A$2:$G$502,6,FALSE()) -> Consumer | K2: =VLOOKUP(C2,Products!$A$2:$E$62,3,FALSE()) -> Electronics | L2: =TEXT(D2,"yyyy-mm") -> 2023-06
A3: 2 | B3: 435 | C3: 59 | D3: 2023-03-15 | E3: 9 | F3: 438.89 | G3: 0 | H3: Completed | I3: 3950.01 | J3: =VLOOKUP(B3,Customers!$A$2:$G$502,6,FALSE()) -> Unknown | K3: =VLOOKUP(C3,Products!$A$2:$E$62,3,FALSE()) -> Furniture | L3: =TEXT(D3,"yyyy-mm") -> 2023-03
A4: 3 | B4: 137 | C4: 39 | D4: 2024-10-22 | E4: 7 | F4: 400.02 | G4: 0.05 | H4: Completed | I4: 2660.13 | J4: =VLOOKUP(B4,Customers!$A$2:$G$502,6,FALSE()) -> Consumer | K4: =VLOOKUP(C4,Products!$A$2:$E$62,3,FALSE()) -> Software | L4: =TEXT(D4,"yyyy-mm") -> 2024-10
A5: 4 | B5: 301 | C5: 34 | D5: 2024-04-06 | E5: 1 | F5: 116.85 | G5: 0.05 | H5: Completed | I5: 111.01 | J5: =VLOOKUP(B5,Customers!$A$2:$G$502,6,FALSE()) -> Corporate | K5: =VLOOKUP(C5,Products!$A$2:$E$62,3,FALSE()) -> Office Supplies | L5: =TEXT(D5,"yyyy-mm") -> 2024-04
A6: 5 | B6: 129 | C6: 48 | D6: 2024-12-18 | E6: 1 | F6: 493.53 | G6: 0.15 | H6: Completed | I6: 419.5 | J6: =VLOOKUP(B6,Customers!$A$2:$G$502,6,FALSE()) -> Corporate | K6: =VLOOKUP(C6,Products!$A$2:$E$62,3,FALSE()) -> Software | L6: =TEXT(D6,"yyyy-mm") -> 2024-12
A7: 6 | B7: 450 | C7: 31 | D7: 2024-07-15 | E7: 9 | F7: 224.86 | G7: 0 | H7: Completed | I7: 2023.74 | J7: =VLOOKUP(B7,Customers!$A$2:$G$502,6,FALSE()) -> Consumer | K7: =VLOOKUP(C7,Products!$A$2:$E$62,3,FALSE()) -> Office Supplies | L7: =TEXT(D7,"yyyy-mm") -> 2024-07
A8: 7 | B8: 135 | C8: 40 | D8: 2023-06-09 | E8: 9 | F8: 193.02 | G8: 0 | H8: Completed | I8: 1737.18 | J8: =VLOOKUP(B8,Customers!$A$2:$G$502,6,FALSE()) -> Corporate | K8: =VLOOKUP(C8,Products!$A$2:$E$62,3,FALSE()) -> Software | L8: =TEXT(D8,"yyyy-mm") -> 2023-06
A9: 8 | B9: 146 | C9: 29 | D9: 2024-10-03 | E9: 4 | F9: 54.62 | G9: 0 | H9: Completed | I9: 218.48 | J9: =VLOOKUP(B9,Customers!$A$2:$G$502,6,FALSE()) -> Consumer | K9: =VLOOKUP(C9,Products!$A$2:$E$62,3,FALSE()) -> Office Supplies | L9: =TEXT(D9,"yyyy-mm") -> 2024-10
A10: 9 | B10: 441 | C10: 59 | D10: 2023-11-30 | E10: 9 | F10: 438.89 | G10: 0.2 | H10: Completed | I10: 3160.01 | J10: =VLOOKUP(B10,Customers!$A$2:$G$502,6,FALSE()) -> Corporate | K10: =VLOOKUP(C10,Products!$A$2:$E$62,3,FALSE()) -> Furniture | L10: =TEXT(D10,"yyyy-mm") -> 2023-11
A11: 10 | B11: 228 | C11: 9 | D11: 2024-12-15 | E11: 3 | F11: 203.1 | G11: 0.1 | H11: Completed | I11: 548.37 | J11: =VLOOKUP(B11,Customers!$A$2:$G$502,6,FALSE()) -> Small Business | K11: =VLOOKUP(C11,Products!$A$2:$E$62,3,FALSE()) -> Electronics | L11: =TEXT(D11,"yyyy-mm") -> 2024-12
A12: 11 | B12: 289 | C12: 28 | D12: 2024-06-20 | E12: 7 | F12: 505.23 | G12: 0.15 | H12: Completed | I12: 3006.12 | J12: =VLOOKUP(B12,Customers!$A$2:$G$502,6,FALSE()) -> Consumer | K12: =VLOOKUP(C12,Products!$A$2:$E$62,3,FALSE()) -> Office Supplies | L12: =TEXT(D12,"yyyy-mm") -> 2024-06
A13: 13 | B13: 418 | C13: 49 | D13: 2023-05-20 | E13: 8 | F13: 325.17 | G13: 0 | H13: Completed | I13: 2601.36 | J13: =VLOOKUP(B13,Customers!$A$2:$G$502,6,FALSE()) -> Corporate | K13: =VLOOKUP(C13,Products!$A$2:$E$62,3,FALSE()) -> Software | L13: =TEXT(D13,"yyyy-mm") -> 2023-05
... A5876: 6000 | B5876: 274 | C5876: 27 | D5876: 2024-06-22 | E5876: 2 | F5876: 772.58 | G5876: 0.15 | H5876: Completed | I5876: 1313.39 | J5876: =VLOOKUP(B5876,Customers!$A$2:$G$502,6,FALSE()) -> Corporate | K5876: =VLOOKUP(C5876,Products!$A$2:$E$62,3,FALSE()) -> Office Supplies | L5876: =TEXT(D5876,"yyyy-mm") -> 2024-06

Sheet Monthly Revenue
A1: Objective: total revenue and orders per month, and % growth vs the previous month.
A3: month | B3: total_revenue | C3: total_orders | D3: prev_month_revenue | E3: growth_pct
A4: 2023-01 | B4: =SUMIFS(Orders!$I$2:$I$5876,Orders!$L$2:$L$5876,A4,Orders!$H$2:$H$5876,"Completed") -> 331982.53 | C4: =COUNTIFS(Orders!$L$2:$L$5876,A4,Orders!$H$2:$H$5876,"Completed") -> 231
A5: 2023-02 | B5: =SUMIFS(Orders!$I$2:$I$5876,Orders!$L$2:$L$5876,A5,Orders!$H$2:$H$5876,"Completed") -> 306938.78 | C5: =COUNTIFS(Orders!$L$2:$L$5876,A5,Orders!$H$2:$H$5876,"Completed") -> 199 | D5: =B4 -> 331982.53 | E5: =IFERROR((B5-D5)/D5,"") -> -0.075436951
A6: 2023-03 | B6: =SUMIFS(Orders!$I$2:$I$5876,Orders!$L$2:$L$5876,A6,Orders!$H$2:$H$5876,"Completed") -> 300613.86 | C6: =COUNTIFS(Orders!$L$2:$L$5876,A6,Orders!$H$2:$H$5876,"Completed") -> 225 | D6: =B5 -> 306938.78 | E6: =IFERROR((B6-D6)/D6,"") -> -0.020606454
A7: 2023-04 | B7: =SUMIFS(Orders!$I$2:$I$5876,Orders!$L$2:$L$5876,A7,Orders!$H$2:$H$5876,"Completed") -> 294101.34 | C7: =COUNTIFS(Orders!$L$2:$L$5876,A7,Orders!$H$2:$H$5876,"Completed") -> 215 | D7: =B6 -> 300613.86 | E7: =IFERROR((B7-D7)/D7,"") -> -0.021664071
A8: 2023-05 | B8: =SUMIFS(Orders!$I$2:$I$5876,Orders!$L$2:$L$5876,A8,Orders!$H$2:$H$5876,"Completed") -> 297200.52 | C8: =COUNTIFS(Orders!$L$2:$L$5876,A8,Orders!$H$2:$H$5876,"Completed") -> 211 | D8: =B7 -> 294101.34 | E8: =IFERROR((B8-D8)/D8,"") -> 0.010537796
A9: 2023-06 | B9: =SUMIFS(Orders!$I$2:$I$5876,Orders!$L$2:$L$5876,A9,Orders!$H$2:$H$5876,"Completed") -> 308502.31 | C9: =COUNTIFS(Orders!$L$2:$L$5876,A9,Orders!$H$2:$H$5876,"Completed") -> 215 | D9: =B8 -> 297200.52 | E9: =IFERROR((B9-D9)/D9,"") -> 0.038027491
A10: 2023-07 | B10: =SUMIFS(Orders!$I$2:$I$5876,Orders!$L$2:$L$5876,A10,Orders!$H$2:$H$5876,"Completed") -> 279382.34 | C10: =COUNTIFS(Orders!$L$2:$L$5876,A10,Orders!$H$2:$H$5876,"Completed") -> 194 | D10: =B9 -> 308502.31 | E10: =IFERROR((B10-D10)/D10,"") -> -0.094391416
A11: 2023-08 | B11: =SUMIFS(Orders!$I$2:$I$5876,Orders!$L$2:$L$5876,A11,Orders!$H$2:$H$5876,"Completed") -> 325608.26 | C11: =COUNTIFS(Orders!$L$2:$L$5876,A11,Orders!$H$2:$H$5876,"Completed") -> 225 | D11: =B10 -> 279382.34 | E11: =IFERROR((B11-D11)/D11,"") -> 0.16545756
A12: 2023-09 | B12: =SUMIFS(Orders!$I$2:$I$5876,Orders!$L$2:$L$5876,A12,Orders!$H$2:$H$5876,"Completed") -> 272650.48 | C12: =COUNTIFS(Orders!$L$2:$L$5876,A12,Orders!$H$2:$H$5876,"Completed") -> 193 | D12: =B11 -> 325608.26 | E12: =IFERROR((B12-D12)/D12,"") -> -0.16264262
A13: 2023-10 | B13: =SUMIFS(Orders!$I$2:$I$5876,Orders!$L$2:$L$5876,A13,Orders!$H$2:$H$5876,"Completed") -> 295846.11 | C13: =COUNTIFS(Orders!$L$2:$L$5876,A13,Orders!$H$2:$H$5876,"Completed") -> 212 | D13: =B12 -> 272650.48 | E13: =IFERROR((B13-D13)/D13,"") -> 0.085074598
A14: 2023-11 | B14: =SUMIFS(Orders!$I$2:$I$5876,Orders!$L$2:$L$5876,A14,Orders!$H$2:$H$5876,"Completed") -> 318365.82 | C14: =COUNTIFS(Orders!$L$2:$L$5876,A14,Orders!$H$2:$H$5876,"Completed") -> 218 | D14: =B13 -> 295846.11 | E14: =IFERROR((B14-D14)/D14,"") -> 0.076119676
A15: 2023-12 | B15: =SUMIFS(Orders!$I$2:$I$5876,Orders!$L$2:$L$5876,A15,Orders!$H$2:$H$5876,"Completed") -> 301862.58 | C15: =COUNTIFS(Orders!$L$2:$L$5876,A15,Orders!$H$2:$H$5876,"Completed") -> 221 | D15: =B14 -> 318365.82 | E15: =IFERROR((B15-D15)/D15,"") -> -0.051837349
A16: 2024-01 | B16: =SUMIFS(Orders!$I$2:$I$5876,Orders!$L$2:$L$5876,A16,Orders!$H$2:$H$5876,"Completed") -> 312116.45 | C16: =COUNTIFS(Orders!$L$2:$L$5876,A16,Orders!$H$2:$H$5876,"Completed") -> 206 | D16: =B15 -> 301862.58 | E16: =IFERROR((B16-D16)/D16,"") -> 0.033968669
... A27: 2024-12 | B27: =SUMIFS(Orders!$I$2:$I$5876,Orders!$L$2:$L$5876,A27,Orders!$H$2:$H$5876,"Completed") -> 335336.58 | C27: =COUNTIFS(Orders!$L$2:$L$5876,A27,Orders!$H$2:$H$5876,"Completed") -> 232 | D27: =B26 -> 252839.32 | E27: =IFERROR((B27-D27)/D27,"") -> 0.32628335

Sheet Top Customers
A1: Objective: top 5 customers by revenue - could be used for a loyalty/retention list.
A3: Top 5
A4: rank | B4: customer_name | C4: segment | D4: total_orders | E4: total_revenue
A5: 1 | B5: =INDEX($I$11:$I$510,MATCH(E5,$L$11:$L$510,0)) -> Valentina Moore | C5: =INDEX($J$11:$J$510,MATCH(E5,$L$11:$L$510,0)) -> Small Business | D5: =INDEX($K$11:$K$510,MATCH(E5,$L$11:$L$510,0)) -> 16 | E5: =LARGE($L$11:$L$510,A5) -> 38263.17
A6: 2 | B6: =INDEX($I$11:$I$510,MATCH(E6,$L$11:$L$510,0)) -> Luis Taylor | C6: =INDEX($J$11:$J$510,MATCH(E6,$L$11:$L$510,0)) -> Consumer | D6: =INDEX($K$11:$K$510,MATCH(E6,$L$11:$L$510,0)) -> 14 | E6: =LARGE($L$11:$L$510,A6) -> 33409.68
A7: 3 | B7: =INDEX($I$11:$I$510,MATCH(E7,$L$11:$L$510,0)) -> Linda Wilson | C7: =INDEX($J$11:$J$510,MATCH(E7,$L$11:$L$510,0)) -> Small Business | D7: =INDEX($K$11:$K$510,MATCH(E7,$L$11:$L$510,0)) -> 13 | E7: =LARGE($L$11:$L$510,A7) -> 31839.05
A8: 4 | B8: =INDEX($I$11:$I$510,MATCH(E8,$L$11:$L$510,0)) -> Susan Thompson | C8: =INDEX($J$11:$J$510,MATCH(E8,$L$11:$L$510,0)) -> Small Business | D8: =INDEX($K$11:$K$510,MATCH(E8,$L$11:$L$510,0)) -> 17 | E8: =LARGE($L$11:$L$510,A8) -> 30422.42
A9: 5 | B9: =INDEX($I$11:$I$510,MATCH(E9,$L$11:$L$510,0)) -> Andres Thomas | C9: =INDEX($J$11:$J$510,MATCH(E9,$L$11:$L$510,0)) -> Consumer | D9: =INDEX($K$11:$K$510,MATCH(E9,$L$11:$L$510,0)) -> 16 | E9: =LARGE($L$11:$L$510,A9) -> 30372.47
H10: All customers (helper table)
H11: customer_id | I11: customer_name | J11: segment | K11: total_orders | L11: total_revenue
H12: 1 | I12: =VLOOKUP(H12,Customers!$A$2:$G$501,2,FALSE()) -> Linda Smith | J12: =VLOOKUP(H12,Customers!$A$2:$G$501,6,FALSE()) -> Consumer | K12: =COUNTIFS(Orders!$B$2:$B$5876,H12,Orders!$H$2:$H$5876,"Completed") -> 8 | L12: =SUMIFS(Orders!$I$2:$I$5876,Orders!$B$2:$B$5876,H12,Orders!$H$2:$H$5876,"Completed") -> 12778.61
H13: 2 | I13: =VLOOKUP(H13,Customers!$A$2:$G$501,2,FALSE()) -> Robert Smith | J13: =VLOOKUP(H13,Customers!$A$2:$G$501,6,FALSE()) -> Small Business | K13: =COUNTIFS(Orders!$B$2:$B$5876,H13,Orders!$H$2:$H$5876,"Completed") -> 10 | L13: =SUMIFS(Orders!$I$2:$I$5876,Orders!$B$2:$B$5876,H13,Orders!$H$2:$H$5876,"Completed") -> 16089.57
H14: 3 | I14: =VLOOKUP(H14,Customers!$A$2:$G$501,2,FALSE()) -> Joseph Anderson | J14: =VLOOKUP(H14,Customers!$A$2:$G$501,6,FALSE()) -> Corporate | K14: =COUNTIFS(Orders!$B$2:$B$5876,H14,Orders!$H$2:$H$5876,"Completed") -> 11 | L14: =SUMIFS(Orders!$I$2:$I$5876,Orders!$B$2:$B$5876,H14,Orders!$H$2:$H$5876,"Completed") -> 18571.83
H15: 4 | I15: =VLOOKUP(H15,Customers!$A$2:$G$501,2,FALSE()) -> Susan Harris | J15: =VLOOKUP(H15,Customers!$A$2:$G$501,6,FALSE()) -> Consumer | K15: =COUNTIFS(Orders!$B$2:$B$5876,H15,Orders!$H$2:$H$5876,"Completed") -> 13 | L15: =SUMIFS(Orders!$I$2:$I$5876,Orders!$B$2:$B$5876,H15,Orders!$H$2:$H$5876,"Completed") -> 19035.15
H16: 5 | I16: =VLOOKUP(H16,Customers!$A$2:$G$501,2,FALSE()) -> Luis Brown | J16: =VLOOKUP(H16,Customers!$A$2:$G$501,6,FALSE()) -> Small Business | K16: =COUNTIFS(Orders!$B$2:$B$5876,H16,Orders!$H$2:$H$5876,"Completed") -> 8 | L16: =SUMIFS(Orders!$I$2:$I$5876,Orders!$B$2:$B$5876,H16,Orders!$H$2:$H$5876,"Completed") -> 8328.67
H17: 6 | I17: =VLOOKUP(H17,Customers!$A$2:$G$501,2,FALSE()) -> John Johnson | J17: =VLOOKUP(H17,Customers!$A$2:$G$501,6,FALSE()) -> Corporate | K17: =COUNTIFS(Orders!$B$2:$B$5876,H17,Orders!$H$2:$H$5876,"Completed") -> 12 | L17: =SUMIFS(Orders!$I$2:$I$5876,Orders!$B$2:$B$5876,H17,Orders!$H$2:$H$5876,"Completed") -> 11477.45
H18: 7 | I18: =VLOOKUP(H18,Customers!$A$2:$G$501,2,FALSE()) -> Lisa Garcia | J18: =VLOOKUP(H18,Customers!$A$2:$G$501,6,FALSE()) -> Small Business | K18: =COUNTIFS(Orders!$B$2:$B$5876,H18,Orders!$H$2:$H$5876,"Completed") -> 14 | L18: =SUMIFS(Orders!$I$2:$I$5876,Orders!$B$2:$B$5876,H18,Orders!$H$2:$H$5876,"Completed") -> 21059.52
H19: 8 | I19: =VLOOKUP(H19,Customers!$A$2:$G$501,2,FALSE()) -> Luis White | J19: =VLOOKUP(H19,Customers!$A$2:$G$501,6,FALSE()) -> Consumer | K19: =COUNTIFS(Orders!$B$2:$B$5876,H19,Orders!$H$2:$H$5876,"Completed") -> 6 | L19: =SUMIFS(Orders!$I$2:$I$5876,Orders!$B$2:$B$5876,H19,Orders!$H$2:$H$5876,"Completed") -> 14261.02
H20: 9 | I20: =VLOOKUP(H20,Customers!$A$2:$G$501,2,FALSE()) -> Patricia Davis | J20: =VLOOKUP(H20,Customers!$A$2:$G$501,6,FALSE()) -> Small Business | K20: =COUNTIFS(Orders!$B$2:$B$5876,H20,Orders!$H$2:$H$5876,"Completed") -> 17 | L20: =SUMIFS(Orders!$I$2:$I$5876,Orders!$B$2:$B$5876,H20,Orders!$H$2:$H$5876,"Completed") -> 16948.28
H21: 10 | I21: =VLOOKUP(H21,Customers!$A$2:$G$501,2,FALSE()) -> Valentina Gonzalez | J21: =VLOOKUP(H21,Customers!$A$2:$G$501,6,FALSE()) -> Small Business | K21: =COUNTIFS(Orders!$B$2:$B$5876,H21,Orders!$H$2:$H$5876,"Completed") -> 14 | L21: =SUMIFS(Orders!$I$2:$I$5876,Orders!$B$2:$B$5876,H21,Orders!$H$2:$H$5876,"Completed") -> 26502.41
H22: 11 | I22: =VLOOKUP(H22,Customers!$A$2:$G$501,2,FALSE()) -> Mariana Gonzalez | J22: =VLOOKUP(H22,Customers!$A$2:$G$501,6,FALSE()) -> Consumer | K22: =COUNTIFS(Orders!$B$2:$B$5876,H22,Orders!$H$2:$H$5876,"Completed") -> 12 | L22: =SUMIFS(Orders!$I$2:$I$5876,Orders!$B$2:$B$5876,H22,Orders!$H$2:$H$5876,"Completed") -> 13795.9
H23: 12 | I23: =VLOOKUP(H23,Customers!$A$2:$G$501,2,FALSE()) -> David Sanchez | J23: =VLOOKUP(H23,Customers!$A$2:$G$501,6,FALSE()) -> Small Business | K23: =COUNTIFS(Orders!$B$2:$B$5876,H23,Orders!$H$2:$H$5876,"Completed") -> 11 | L23: =SUMIFS(Orders!$I$2:$I$5876,Orders!$B$2:$B$5876,H23,Orders!$H$2:$H$5876,"Completed") -> 22575.32
... H511: 500 | I511: =VLOOKUP(H511,Customers!$A$2:$G$501,2,FALSE()) -> Charles Lopez | J511: =VLOOKUP(H511,Customers!$A$2:$G$501,6,FALSE()) -> Small Business | K511: =COUNTIFS(Orders!$B$2:$B$5876,H511,Orders!$H$2:$H$5876,"Completed") -> 2 | L511: =SUMIFS(Orders!$I$2:$I$5876,Orders!$B$2:$B$5876,H511,Orders!$H$2:$H$5876,"Completed") -> 913.39

Sheet Product Performance
A1: Objective: units sold, revenue and profit per product, and rolled up by category.
A3: By product
A4: product_id | B4: product_name | C4: category | D4: unit_cost | E4: units_sold | F4: total_revenue | G4: total_cost | H4: total_profit
A5: 1 | B5: =VLOOKUP(A5,Products!$A$2:$E$61,2,FALSE()) -> Wireless Mouse | C5: =VLOOKUP(A5,Products!$A$2:$E$61,3,FALSE()) -> Electronics | D5: =VLOOKUP(A5,Products!$A$2:$E$61,4,FALSE()) -> 152.94 | E5: =SUMIFS(Orders!$E$2:$E$5876,Orders!$C$2:$C$5876,A5,Orders!$H$2:$H$5876,"Completed") -> 437 | F5: =SUMIFS(Orders!$I$2:$I$5876,Orders!$C$2:$C$5876,A5,Orders!$H$2:$H$5876,"Completed") -> 133104.69 | G5: =D5*E5 -> 66834.78 | H5: =F5-G5 -> 66269.91
A6: 2 | B6: =VLOOKUP(A6,Products!$A$2:$E$61,2,FALSE()) -> Mechanical Keyboard | C6: =VLOOKUP(A6,Products!$A$2:$E$61,3,FALSE()) -> Electronics | D6: =VLOOKUP(A6,Products!$A$2:$E$61,4,FALSE()) -> 294.14 | E6: =SUMIFS(Orders!$E$2:$E$5876,Orders!$C$2:$C$5876,A6,Orders!$H$2:$H$5876,"Completed") -> 393 | F6: =SUMIFS(Orders!$I$2:$I$5876,Orders!$C$2:$C$5876,A6,Orders!$H$2:$H$5876,"Completed") -> 180380.13 | G6: =D6*E6 -> 115597.02 | H6: =F6-G6 -> 64783.11
A7: 3 | B7: =VLOOKUP(A7,Products!$A$2:$E$61,2,FALSE()) -> USB-C Hub | C7: =VLOOKUP(A7,Products!$A$2:$E$61,3,FALSE()) -> Electronics | D7: =VLOOKUP(A7,Products!$A$2:$E$61,4,FALSE()) -> 66.63 | E7: =SUMIFS(Orders!$E$2:$E$5876,Orders!$C$2:$C$5876,A7,Orders!$H$2:$H$5876,"Completed") -> 396 | F7: =SUMIFS(Orders!$I$2:$I$5876,Orders!$C$2:$C$5876,A7,Orders!$H$2:$H$5876,"Completed") -> 33355.86 | G7: =D7*E7 -> 26385.48 | H7: =F7-G7 -> 6970.38
A8: 4 | B8: =VLOOKUP(A8,Products!$A$2:$E$61,2,FALSE()) -> 27in Monitor | C8: =VLOOKUP(A8,Products!$A$2:$E$61,3,FALSE()) -> Electronics | D8: =VLOOKUP(A8,Products!$A$2:$E$61,4,FALSE()) -> 27.94 | E8: =SUMIFS(Orders!$E$2:$E$5876,Orders!$C$2:$C$5876,A8,Orders!$H$2:$H$5876,"Completed") -> 353 | F8: =SUMIFS(Orders!$I$2:$I$5876,Orders!$C$2:$C$5876,A8,Orders!$H$2:$H$5876,"Completed") -> 18533.92 | G8: =D8*E8 -> 9862.82 | H8: =F8-G8 -> 8671.1
A9: 5 | B9: =VLOOKUP(A9,Products!$A$2:$E$61,2,FALSE()) -> Webcam HD | C9: =VLOOKUP(A9,Products!$A$2:$E$61,3,FALSE()) -> Electronics | D9: =VLOOKUP(A9,Products!$A$2:$E$61,4,FALSE()) -> 242.44 | E9: =SUMIFS(Orders!$E$2:$E$5876,Orders!$C$2:$C$5876,A9,Orders!$H$2:$H$5876,"Completed") -> 399 | F9: =SUMIFS(Orders!$I$2:$I$5876,Orders!$C$2:$C$5876,A9,Orders!$H$2:$H$5876,"Completed") -> 163659.59 | G9: =D9*E9 -> 96733.56 | H9: =F9-G9 -> 66926.03
A10: 6 | B10: =VLOOKUP(A10,Products!$A$2:$E$61,2,FALSE()) -> Noise Cancelling Headset | C10: =VLOOKUP(A10,Products!$A$2:$E$61,3,FALSE()) -> Electronics | D10: =VLOOKUP(A10,Products!$A$2:$E$61,4,FALSE()) -> 13.13 | E10: =SUMIFS(Orders!$E$2:$E$5876,Orders!$C$2:$C$5876,A10,Orders!$H$2:$H$5876,"Completed") -> 401 | F10: =SUMIFS(Orders!$I$2:$I$5876,Orders!$C$2:$C$5876,A10,Orders!$H$2:$H$5876,"Completed") -> 10483.12 | G10: =D10*E10 -> 5265.13 | H10: =F10-G10 -> 5217.99
A11: 7 | B11: =VLOOKUP(A11,Products!$A$2:$E$61,2,FALSE()) -> Portable SSD 1TB | C11: =VLOOKUP(A11,Products!$A$2:$E$61,3,FALSE()) -> Electronics | D11: =VLOOKUP(A11,Products!$A$2:$E$61,4,FALSE()) -> 333.81 | E11: =SUMIFS(Orders!$E$2:$E$5876,Orders!$C$2:$C$5876,A11,Orders!$H$2:$H$5876,"Completed") -> 451 | F11: =SUMIFS(Orders!$I$2:$I$5876,Orders!$C$2:$C$5876,A11,Orders!$H$2:$H$5876,"Completed") -> 194396 | G11: =D11*E11 -> 150548.31 | H11: =F11-G11 -> 43847.69
A12: 8 | B12: =VLOOKUP(A12,Products!$A$2:$E$61,2,FALSE()) -> Laptop Stand | C12: =VLOOKUP(A12,Products!$A$2:$E$61,3,FALSE()) -> Electronics | D12: =VLOOKUP(A12,Products!$A$2:$E$61,4,FALSE()) -> 76.82 | E12: =SUMIFS(Orders!$E$2:$E$5876,Orders!$C$2:$C$5876,A12,Orders!$H$2:$H$5876,"Completed") -> 491 | F12: =SUMIFS(Orders!$I$2:$I$5876,Orders!$C$2:$C$5876,A12,Orders!$H$2:$H$5876,"Completed") -> 47434.14 | G12: =D12*E12 -> 37718.62 | H12: =F12-G12 -> 9715.52
A13: 9 | B13: =VLOOKUP(A13,Products!$A$2:$E$61,2,FALSE()) -> Bluetooth Speaker | C13: =VLOOKUP(A13,Products!$A$2:$E$61,3,FALSE()) -> Electronics | D13: =VLOOKUP(A13,Products!$A$2:$E$61,4,FALSE()) -> 125.18 | E13: =SUMIFS(Orders!$E$2:$E$5876,Orders!$C$2:$C$5876,A13,Orders!$H$2:$H$5876,"Completed") -> 554 | F13: =SUMIFS(Orders!$I$2:$I$5876,Orders!$C$2:$C$5876,A13,Orders!$H$2:$H$5876,"Completed") -> 104169.97 | G13: =D13*E13 -> 69349.72 | H13: =F13-G13 -> 34820.25
A14: 10 | B14: =VLOOKUP(A14,Products!$A$2:$E$61,2,FALSE()) -> Wireless Mouse | C14: =VLOOKUP(A14,Products!$A$2:$E$61,3,FALSE()) -> Electronics | D14: =VLOOKUP(A14,Products!$A$2:$E$61,4,FALSE()) -> 175.62 | E14: =SUMIFS(Orders!$E$2:$E$5876,Orders!$C$2:$C$5876,A14,Orders!$H$2:$H$5876,"Completed") -> 467 | F14: =SUMIFS(Orders!$I$2:$I$5876,Orders!$C$2:$C$5876,A14,Orders!$H$2:$H$5876,"Completed") -> 109550.52 | G14: =D14*E14 -> 82014.54 | H14: =F14-G14 -> 27535.98
A15: 11 | B15: =VLOOKUP(A15,Products!$A$2:$E$61,2,FALSE()) -> Mechanical Keyboard | C15: =VLOOKUP(A15,Products!$A$2:$E$61,3,FALSE()) -> Electronics | D15: =VLOOKUP(A15,Products!$A$2:$E$61,4,FALSE()) -> 246.68 | E15: =SUMIFS(Orders!$E$2:$E$5876,Orders!$C$2:$C$5876,A15,Orders!$H$2:$H$5876,"Completed") -> 420 | F15: =SUMIFS(Orders!$I$2:$I$5876,Orders!$C$2:$C$5876,A15,Orders!$H$2:$H$5876,"Completed") -> 127710.82 | G15: =D15*E15 -> 103605.6 | H15: =F15-G15 -> 24105.22
A16: 12 | B16: =VLOOKUP(A16,Products!$A$2:$E$61,2,FALSE()) -> USB-C Hub | C16: =VLOOKUP(A16,Products!$A$2:$E$61,3,FALSE()) -> Electronics | D16: =VLOOKUP(A16,Products!$A$2:$E$61,4,FALSE()) -> 120.4 | E16: =SUMIFS(Orders!$E$2:$E$5876,Orders!$C$2:$C$5876,A16,Orders!$H$2:$H$5876,"Completed") -> 401 | F16: =SUMIFS(Orders!$I$2:$I$5876,Orders!$C$2:$C$5876,A16,Orders!$H$2:$H$5876,"Completed") -> 66691.47 | G16: =D16*E16 -> 48280.4 | H16: =F16-G16 -> 18411.07
... A64: 60 | B64: =VLOOKUP(A64,Products!$A$2:$E$61,2,FALSE()) -> Conference Table | C64: =VLOOKUP(A64,Products!$A$2:$E$61,3,FALSE()) -> Furniture | D64: =VLOOKUP(A64,Products!$A$2:$E$61,4,FALSE()) -> 357.56 | E64: =SUMIFS(Orders!$E$2:$E$5876,Orders!$C$2:$C$5876,A64,Orders!$H$2:$H$5876,"Completed") -> 511 | F64: =SUMIFS(Orders!$I$2:$I$5876,Orders!$C$2:$C$5876,A64,Orders!$H$2:$H$5876,"Completed") -> 277602.24 | G64: =D64*E64 -> 182713.16 | H64: =F64-G64 -> 94889.08
A66: By category
A67: category | B67: total_revenue | C67: total_profit
A68: Electronics | B68: =SUMIF($C$5:$C$64,A68,$F$5:$F$64) -> 1906682.1 | C68: =SUMIF($C$5:$C$64,A68,$H$5:$H$64) -> 624284.2
A69: Furniture | B69: =SUMIF($C$5:$C$64,A69,$F$5:$F$64) -> 1102504 | C69: =SUMIF($C$5:$C$64,A69,$H$5:$H$64) -> 393733.12
A70: Office Supplies | B70: =SUMIF($C$5:$C$64,A70,$F$5:$F$64) -> 1881216.4 | C70: =SUMIF($C$5:$C$64,A70,$H$5:$H$64) -> 701030.08
A71: Software | B71: =SUMIF($C$5:$C$64,A71,$F$5:$F$64) -> 2387780.4 | C71: =SUMIF($C$5:$C$64,A71,$H$5:$H$64) -> 761233.01

Sheet Segment Summary
A1: Objective: revenue and orders by customer segment (Consumer/Corporate/Small Business/Unknown).
A3: segment | B3: total_orders | C3: total_revenue
A4: Consumer | B4: =COUNTIFS(Orders!$J$2:$J$5876,A4,Orders!$H$2:$H$5876,"Completed") -> 1620 | C4: =SUMIFS(Orders!$I$2:$I$5876,Orders!$J$2:$J$5876,A4,Orders!$H$2:$H$5876,"Completed") -> 2349333.9
A5: Corporate | B5: =COUNTIFS(Orders!$J$2:$J$5876,A5,Orders!$H$2:$H$5876,"Completed") -> 1707 | C5: =SUMIFS(Orders!$I$2:$I$5876,Orders!$J$2:$J$5876,A5,Orders!$H$2:$H$5876,"Completed") -> 2365056.3
A6: Small Business | B6: =COUNTIFS(Orders!$J$2:$J$5876,A6,Orders!$H$2:$H$5876,"Completed") -> 1670 | C6: =SUMIFS(Orders!$I$2:$I$5876,Orders!$J$2:$J$5876,A6,Orders!$H$2:$H$5876,"Completed") -> 2356324.2
A7: Unknown | B7: =COUNTIFS(Orders!$J$2:$J$5876,A7,Orders!$H$2:$H$5876,"Completed") -> 136 | C7: =SUMIFS(Orders!$I$2:$I$5876,Orders!$J$2:$J$5876,A7,Orders!$H$2:$H$5876,"Completed") -> 207468.56

Sheet Order Status
A1: Objective: breakdown of orders by status, and % of total.
A3: order_status | B3: total_orders | C3: pct_of_total
A4: Completed | B4: =COUNTIF(Orders!$H$2:$H$5876,A4) -> 5133 | C4: =B4/COUNTA(Orders!$H$2:$H$5876) -> 0.87370213
A5: Cancelled | B5: =COUNTIF(Orders!$H$2:$H$5876,A5) -> 370 | C5: =B5/COUNTA(Orders!$H$2:$H$5876) -> 0.062978723
A6: Returned | B6: =COUNTIF(Orders!$H$2:$H$5876,A6) -> 372 | C6: =B6/COUNTA(Orders!$H$2:$H$5876) -> 0.063319149
